Workbook
Name الاسم: Stock_New!$A$1:$A$273

Sheet Dashboard
A1: Product Name | B1: Total Qty | C1: Cost | D1: Revenue | E1: Profit Per Unit | F1: Total Profit | G1: Last Sale Date
A2: {=UNIQUE(Sales_New!A2:A4745)} -> بوت تركي | B2: {=IF(A2:A4745="","",SUMIF(Sales_New!A:A, A2:A4745, Sales_New!C:C))} -> 6 | C2: =IF($A2="", "", IFERROR(VLOOKUP($A2, Stock_New!$A:$M, 4, FALSE), "")) -> 105 | D2: =IF($A2="", "", IFERROR(VLOOKUP($A2, Stock_New!$A:$M, 6, FALSE), "")) -> 126 | E2: =D2-C2 -> 21 | F2: =B2*D2-B2*C2 -> 126
A3: شجرة تركيب 12 ورقة | B3: 2 | C3: =IF($A3="", "", IFERROR(VLOOKUP($A3, Stock_New!$A:$M, 4, FALSE), "")) -> 95 | D3: =IF($A3="", "", IFERROR(VLOOKUP($A3, Stock_New!$A:$M, 6, FALSE), "")) -> 114 | E3: =D3-C3 -> 19 | F3: =B3*D3-B3*C3 -> 38
A4: بوكيه خزف | B4: 1 | C4: =IF($A4="", "", IFERROR(VLOOKUP($A4, Stock_New!$A:$M, 4, FALSE), "")) -> 140 | D4: =IF($A4="", "", IFERROR(VLOOKUP($A4, Stock_New!$A:$M, 6, FALSE), "")) -> 168 | E4: =D4-C4 -> 28 | F4: =B4*D4-B4*C4 -> 28
A5: فازة خزف وورد احمر صغير | B5: 4 | C5: =IF($A5="", "", IFERROR(VLOOKUP($A5, Stock_New!$A:$M, 4, FALSE), "")) -> 135 | D5: =IF($A5="", "", IFERROR(VLOOKUP($A5, Stock_New!$A:$M, 6, FALSE), "")) -> 162 | E5: =D5-C5 -> 27 | F5: =B5*D5-B5*C5 -> 108
A6: فازة خزف وبوكيه ابيض كبير | B6: 1 | C6: =IF($A6="", "", IFERROR(VLOOKUP($A6, Stock_New!$A:$M, 4, FALSE), "")) -> 185 | D6: =IF($A6="", "", IFERROR(VLOOKUP($A6, Stock_New!$A:$M, 6, FALSE), "")) -> 222 | E6: =D6-C6 -> 37 | F6: =B6*D6-B6*C6 -> 37
A7: مزرعة | B7: 53 | C7: =IF($A7="", "", IFERROR(VLOOKUP($A7, Stock_New!$A:$M, 4, FALSE), "")) -> 37 | D7: =IF($A7="", "", IFERROR(VLOOKUP($A7, Stock_New!$A:$M, 6, FALSE), "")) -> 44.4 | E7: =D7-C7 -> 7.4 | F7: =B7*D7-B7*C7 -> 392.2
A8: شجرة ورق عريض | B8: 6 | C8: =IF($A8="", "", IFERROR(VLOOKUP($A8, Stock_New!$A:$M, 4, FALSE), "")) -> 195 | D8: =IF($A8="", "", IFERROR(VLOOKUP($A8, Stock_New!$A:$M, 6, FALSE), "")) -> 234 | E8: =D8-C8 -> 39 | F8: =B8*D8-B8*C8 -> 234
A9: بوكيه ورد احمر صغير واخضر | B9: 2 | C9: =IF($A9="", "", IFERROR(VLOOKUP($A9, Stock_New!$A:$M, 4, FALSE), "")) -> 170 | D9: =IF($A9="", "", IFERROR(VLOOKUP($A9, Stock_New!$A:$M, 6, FALSE), "")) -> 204 | E9: =D9-C9 -> 34 | F9: =B9*D9-B9*C9 -> 68
A10: مج بشاليموه | B10: 5 | C10: =IF($A10="", "", IFERROR(VLOOKUP($A10, Stock_New!$A:$M, 4, FALSE), "")) -> 75 | D10: =IF($A10="", "", IFERROR(VLOOKUP($A10, Stock_New!$A:$M, 6, FALSE), "")) -> 90 | E10: =D10-C10 -> 15 | F10: =B10*D10-B10*C10 -> 75
A11: اشكال السيرفرات | B11: 9 | C11: =IF($A11="", "", IFERROR(VLOOKUP($A11, Stock_New!$A:$M, 4, FALSE), "")) -> 120 | D11: =IF($A11="", "", IFERROR(VLOOKUP($A11, Stock_New!$A:$M, 6, FALSE), "")) -> 144 | E11: =D11-C11 -> 24 | F11: =B11*D11-B11*C11 -> 216
A12: مبخرة غزالة | B12: 10 | C12: =IF($A12="", "", IFERROR(VLOOKUP($A12, Stock_New!$A:$M, 4, FALSE), "")) -> 60 | D12: =IF($A12="", "", IFERROR(VLOOKUP($A12, Stock_New!$A:$M, 6, FALSE), "")) -> 72 | E12: =D12-C12 -> 12 | F12: =B12*D12-B12*C12 -> 120
A13: بوكيه بلاستيك وورد احمر | B13: 1 | C13: =IF($A13="", "", IFERROR(VLOOKUP($A13, Stock_New!$A:$M, 4, FALSE), "")) -> 220 | D13: =IF($A13="", "", IFERROR(VLOOKUP($A13, Stock_New!$A:$M, 6, FALSE), "")) -> 264 | E13: =D13-C13 -> 44 | F13: =B13*D13-B13*C13 -> 44
A14: بوكيه بلاستيك ورد كبير | B14: 1 | C14: =IF($A14="", "", IFERROR(VLOOKUP($A14, Stock_New!$A:$M, 4, FALSE), "")) -> 175 | D14: =IF($A14="", "", IFERROR(VLOOKUP($A14, Stock_New!$A:$M, 6, FALSE), "")) -> 210 | E14: =D14-C14 -> 35 | F14: =B14*D14-B14*C14 -> 35
... A103: فازة بورسلين | B103: 8 | C103: =IF($A103="", "", IFERROR(VLOOKUP($A103, Stock_New!$A:$M, 4, FALSE), "")) -> 195 | D103: =IF($A103="", "", IFERROR(VLOOKUP($A103, Stock_New!$A:$M, 6, FALSE), "")) -> 234 | E103: =D103-C103 -> 39 | F103: =B103*D103-B103*C103 -> 312
C104: =IF($A104="", "", IFERROR(VLOOKUP($A104, Stock_New!$A:$M, 4, FALSE), "")) | D104: =IF($A104="", "", IFERROR(VLOOKUP($A104, Stock_New!$A:$M, 6, FALSE), "")) | E104: =D104-C104 -> 0 | F104: =B104*D104-B104*C104 -> 0
A105: طقم ترمص | B105: 4 | C105: =IF($A105="", "", IFERROR(VLOOKUP($A105, Stock_New!$A:$M, 4, FALSE), "")) -> 165 | D105: =IF($A105="", "", IFERROR(VLOOKUP($A105, Stock_New!$A:$M, 6, FALSE), "")) -> 198 | E105: =D105-C105 -> 33 | F105: =B105*D105-B105*C105 -> 132
A106: شوكة وسط | B106: 5 | C106: =IF($A106="", "", IFERROR(VLOOKUP($A106, Stock_New!$A:$M, 4, FALSE), "")) -> 155 | D106: =IF($A106="", "", IFERROR(VLOOKUP($A106, Stock_New!$A:$M, 6, FALSE), "")) -> 186 | E106: =D106-C106 -> 31 | F106: =B106*D106-B106*C106 -> 155
A107: فازة خزف صغيرة تركي | B107: 10 | C107: =IF($A107="", "", IFERROR(VLOOKUP($A107, Stock_New!$A:$M, 4, FALSE), "")) -> 40 | D107: =IF($A107="", "", IFERROR(VLOOKUP($A107, Stock_New!$A:$M, 6, FALSE), "")) -> 48 | E107: =D107-C107 -> 8 | F107: =B107*D107-B107*C107 -> 80
A108: بوكيه مشمش | B108: 5 | C108: =IF($A108="", "", IFERROR(VLOOKUP($A108, Stock_New!$A:$M, 4, FALSE), "")) -> 50 | D108: =IF($A108="", "", IFERROR(VLOOKUP($A108, Stock_New!$A:$M, 6, FALSE), "")) -> 60 | E108: =D108-C108 -> 10 | F108: =B108*D108-B108*C108 -> 50
A109: قرنفل جيبسفيل | B109: 6.3333333 | C109: =IF($A109="", "", IFERROR(VLOOKUP($A109, Stock_New!$A:$M, 4, FALSE), "")) -> 75 | D109: =IF($A109="", "", IFERROR(VLOOKUP($A109, Stock_New!$A:$M, 6, FALSE), "")) -> 90 | E109: =D109-C109 -> 15 | F109: =B109*D109-B109*C109 -> 95
A110: شجرة مشمش فرعين | B110: 3 | C110: =IF($A110="", "", IFERROR(VLOOKUP($A110, Stock_New!$A:$M, 4, FALSE), "")) -> 175 | D110: =IF($A110="", "", IFERROR(VLOOKUP($A110, Stock_New!$A:$M, 6, FALSE), "")) -> 210 | E110: =D110-C110 -> 35 | F110: =B110*D110-B110*C110 -> 105
A111: مبخرة كهرباء 002/7 | B111: 1 | C111: =IF($A111="", "", IFERROR(VLOOKUP($A111, Stock_New!$A:$M, 4, FALSE), "")) -> 167.5 | D111: =IF($A111="", "", IFERROR(VLOOKUP($A111, Stock_New!$A:$M, 6, FALSE), "")) -> 201 | E111: =D111-C111 -> 33.5 | F111: =B111*D111-B111*C111 -> 33.5
A112: بخور ميسك كيس 5097 | B112: 6 | C112: =IF($A112="", "", IFERROR(VLOOKUP($A112, Stock_New!$A:$M, 4, FALSE), "")) | D112: =IF($A112="", "", IFERROR(VLOOKUP($A112, Stock_New!$A:$M, 6, FALSE), "")) | E112: =D112-C112 -> 0 | F112: =B112*D112-B112*C112 -> 0
A113: شمع 006/96 | B113: 14 | C113: =IF($A113="", "", IFERROR(VLOOKUP($A113, Stock_New!$A:$M, 4, FALSE), "")) -> 11.13 | D113: =IF($A113="", "", IFERROR(VLOOKUP($A113, Stock_New!$A:$M, 6, FALSE), "")) -> 13.36 | E113: =D113-C113 -> 2.23 | F113: =B113*D113-B113*C113 -> 31.22
A114: شوكة صغيرة | B114: 6 | C114: =IF($A114="", "", IFERROR(VLOOKUP($A114, Stock_New!$A:$M, 4, FALSE), "")) -> 130 | D114: =IF($A114="", "", IFERROR(VLOOKUP($A114, Stock_New!$A:$M, 6, FALSE), "")) -> 156 | E114: =D114-C114 -> 26 | F114: =B114*D114-B114*C114 -> 156
A115: بوكية اربع وردات | B115: 4 | C115: =IF($A115="", "", IFERROR(VLOOKUP($A115, Stock_New!$A:$M, 4, FALSE), "")) -> 85 | D115: =IF($A115="", "", IFERROR(VLOOKUP($A115, Stock_New!$A:$M, 6, FALSE), "")) -> 102 | E115: =D115-C115 -> 17 | F115: =B115*D115-B115*C115 -> 68
A116: أباجورة USB ناش 358 (عرض خاص) | B116: 2 | C116: =IF($A116="", "", IFERROR(VLOOKUP($A116, Stock_New!$A:$M, 4, FALSE), "")) -> 135 | D116: =IF($A116="", "", IFERROR(VLOOKUP($A116, Stock_New!$A:$M, 6, FALSE), "")) -> 162 | E116: =D116-C116 -> 27 | F116: =B116*D116-B116*C116 -> 54
... A315: مكعب روبيك ك 551 | B315: 3 | C315: =IF($A315="", "", IFERROR(VLOOKUP($A315, Stock_New!$A:$M, 4, FALSE), "")) -> 15 | D315: =IF($A315="", "", IFERROR(VLOOKUP($A315, Stock_New!$A:$M, 6, FALSE), "")) -> 18 | E315: =D315-C315 -> 3 | F315: =B315*D315-B315*C315 -> 9
A316: بولة خزف صغيرة | B316: 3
A317: مقزم مشمش | B317: 30
A318: عربية كروم صوت + نور 630 | B318: 2
A319: نيشان دارتس 482/1 | B319: 2
A320: نافورة ديكور 270 sm | B320: 1
A321: مبخرة فحم 3788 | B321: 1
A322: بلدي فرسان 24 | B322: 1
A323: بوكيه مشمش الفرسان | B323: 2
A324: ورد ديكور محمد رشدي | B324: 6
A325: مبخرة فحم 3207 | B325: 1
A326: شنطة هدايا صغير عادي | B326: 1
...

Sheet Stock_New
A1: Product Name | B1: ItemType | C1: Supplier | D1: AvgPurchasePrice | E1: AvailableQty | F1: SuggestedSalePrice | G1: LastUpdate | H1: TotalPurchasedQty | I1: TotalSoldQty | J1: TotalPurchaseValue | K1: TotalSalesValue | L1: LastUsageNote | M1: Toal Available
A2: موديل رقم 2052 | B2: سيلفرات | C2: ذكريا | D2: 1599 | E2: 1 | F2: 1918.8 | G2: 45856 | H2: 1 | I2: 0 | J2: 1599 | K2: 0 | M2: 1599
A3: موديل رقم 2053 | B3: سيلفرات | C3: ذكريا | D3: 1599 | E3: 1 | F3: 1918.8 | G3: 45856 | H3: 1 | I3: 0 | J3: 1599 | K3: 0 | M3: 1599
A4: موديل رقم 2058 | B4: سيلفرات | C4: ذكريا | D4: 1499 | E4: 1 | F4: 1798.8 | G4: 45856 | H4: 1 | I4: 0 | J4: 1499 | K4: 0 | M4: 1499
A5: موديل رقم 2057 | B5: سيلفرات | C5: ذكريا | D5: 1499 | E5: 0 | F5: 1798.8 | G5: 46090 | H5: 1 | I5: 1 | J5: 1499 | K5: 1500 | M5: 0
A6: موديل رقم 2051 | B6: سيلفرات | C6: ذكريا | D6: 1399 | E6: 2 | F6: 1678.8 | G6: 45856 | H6: 2 | I6: 0 | J6: 2798 | K6: 0 | M6: 2798
A7: موديل رقم 2043 | B7: سيلفرات | C7: ذكريا | D7: 1299 | E7: 1 | F7: 1558.8 | G7: 45856 | H7: 1 | I7: 0 | J7: 1299 | K7: 0 | M7: 1299
A8: موديل رقم 2042 | B8: سيلفرات | C8: ذكريا | D8: 1299 | E8: 1 | F8: 1558.8 | G8: 45856 | H8: 1 | I8: 0 | J8: 1299 | K8: 0 | M8: 1299
A9: موديل رقم 2001 | B9: سيلفرات | C9: ذكريا | D9: 1250 | E9: 1 | F9: 1500 | G9: 45856 | H9: 1 | I9: 0 | J9: 1250 | K9: 0 | M9: 1250
A10: موديل رقم 2003 | B10: سيلفرات | C10: ذكريا | D10: 1100 | E10: 2 | F10: 1320 | G10: 45856 | H10: 2 | I10: 0 | J10: 2200 | K10: 0 | M10: 2200
A11: سيكس ليف 5 جزع 170 سم | B11: شجر | C11: شركة الفرسان | D11: 1100 | E11: 1 | F11: 1320 | G11: 45987 | H11: 1 | I11: 0 | J11: 1100 | K11: 0 | M11: 1100
A12: موديل 935 | B12: سيلفرات | C12: ذكريا | D12: 999 | E12: 1 | F12: 1198.8 | G12: 45856 | H12: 1 | I12: 0 | J12: 999 | K12: 0 | M12: 999
A13: موديل 936 | B13: سيلفرات | C13: ذكريا | D13: 999 | E13: 1 | F13: 1198.8 | G13: 45856 | H13: 1 | I13: 0 | J13: 999 | K13: 0 | M13: 999
... A15: فازة ازاز كبيره وبوكيه | B15: بوكيه | C15: ذكريا | D15: 725 | E15: 1 | F15: 870 | G15: 45812 | H15: 1 | I15: 0 | J15: 725 | K15: 0 | M15: 725
A16: طقم باسكت | B16: سيلفرات | C16: ذكريا | D16: 725 | E16: 1 | F16: 870 | G16: done | H16: 2 | I16: 1 | J16: 1450 | K16: 934.53 | M16: 725
A17: شجرة موز 6 فرع | B17: شجر | C17: ذكريا | D17: 725 | E17: 1 | F17: 870 | G17: 45812 | H17: 1 | I17: 0 | J17: 725 | K17: 0 | M17: 725
A18: شمعدان نخلة | B18: سيلفرات | C18: ذكريا | D18: 625 | E18: 0 | F18: 750 | G18: 45945 | H18: 1 | I18: 1 | J18: 625 | K18: 800 | M18: 0
A19: شمعدان كريستال | B19: سيلفرات | C19: ذكريا | D19: 598.33 | E19: 1 | F19: 718 | G19: 46089 | H19: 3 | I19: 2 | J19: 1795 | K19: 1524.6 | M19: 598.33
A20: بونبونيرة عجلة | B20: سيلفرات | C20: ذكريا | D20: 575 | E20: 0 | F20: 690 | G20: 45898 | H20: 1 | I20: 1 | J20: 575 | K20: 700 | M20: 0
A21: شجرة ذرة وسط | B21: شجر | C21: ذكريا | D21: 575 | E21: 0 | F21: 690 | G21: 46037.857 | H21: 1 | I21: 1 | J21: 575 | K21: 600 | M21: 0
A22: شجرة موز 9 فرع | B22: شجر | C22: ذكريا | D22: 575 | E22: 0 | F22: 690 | G22: 46095.936 | H22: 1 | I22: 1 | J22: 575 | K22: 600 | M22: 0
A23: شجرة اريكا وسط | B23: شجر | C23: ذكريا | D23: 562.5 | E23: 0 | F23: 675 | G23: 46095.936 | H23: 2 | I23: 2 | J23: 1125 | K23: 1374.29 | M23: 0
A24: طقم بلورة زجاج | B24: سيلفرات | C24: ذكريا | D24: 525 | E24: 1 | F24: 630 | G24: 45835 | H24: 1 | I24: 0 | J24: 525 | K24: 0 | M24: 525
A25: شيالة ازاز 3 خلص | B25: سيلفر | C25: ذكريا | D25: 525 | E25: 0 | F25: 630 | G25: 45957 | H25: 1 | I25: 1 | J25: 525 | K25: 630 | M25: 0
A26: شجرة موز خمسة جزع 130 سم | B26: شجر | C26: شركة الفرسان | D26: 500 | E26: 1 | F26: 600 | G26: 45987 | H26: 1 | I26: 0 | J26: 500 | K26: 0 | M26: 500
A27: نافورة 1934 | B27: ديكور مكتب | C27: سنتر محمد رشدي | D27: 499 | E27: 0 | F27: 598.8 | G27: 46160 | H27: 1 | I27: 1 | J27: 499 | K27: 650 | M27: 499
A28: نافورة ديكور 10883 | B28: تحف | C28: محمد رشدي | D28: 490 | E28: 0 | F28: 588 | G28: 46100 | H28: 2 | I28: 2 | J28: 980 | K28: 1250 | M28: 0
... A33: بوت هاند ميد كبير | B33: بوكيه | C33: ذكريا | D33: 425 | E33: 2 | F33: 510 | G33: 45856 | H33: 2 | I33: 0 | J33: 850 | K33: 0 | M33: 850
A34: بوكيه كريستال شفاف وبوكيه اخضر | B34: بوكيه | C34: ذكريا | D34: =330+90 -> 420 | E34: 1 | F34: 612 | G34: 45835 | H34: 1 | I34: 0 | J34: 510 | K34: 0 | M34: 510
A35: طقم زجاج ابيض وريش وورد صغير | B35: بوكيه | C35: ذكريا | D35: 415 | E35: 1 | F35: 498 | G35: 45812 | H35: 1 | I35: 0 | J35: 415 | K35: 0 | M35: 415
A36: شجرة نجمة جلد | B36: شجر | C36: شركة حسين علي | D36: 412.5 | E36: 4 | F36: 495 | G36: 46116 | H36: 8 | I36: 4 | J36: 3300 | K36: 2000 | M36: 1650
A37: شجرة مانجا 18 ورقة | B37: شجر | C37: ذكريا | D37: 400 | E37: 0 | F37: 480 | G37: 45919 | H37: 1 | I37: 1 | J37: 400 | K37: 480 | M37: 0
A38: شجرة بامبو | B38: شجر | C38: ذكريا | D38: 400 | E38: 1 | F38: 480 | G38: 45812 | H38: 1 | I38: 0 | J38: 400 | K38: 0 | M38: 400
A39: فازة بورسلين كبيرة ابيض مذهب | B39: بورسلين | C39: شركة حسين علي | D39: 400 | E39: 3 | F39: 480 | G39: 46095 | H39: 3 | I39: 0 | J39: 1200 | K39: 0 | M39: 1200
A40: بوكيه فازة بورسلين دهبي وورد شبه التاج | B40: بوكيه | C40: ذكريا | D40: 385 | E40: 0 | F40: 462 | G40: 45901 | H40: 1 | I40: 1 | J40: 385 | K40: 490 | M40: 0
A41: شجرة موز صغيرة درجة عالية | B41: شجر | C41: ذكريا | D41: 375 | E41: 1 | F41: 450 | G41: 45929 | H41: 1 | I41: 0 | J41: 375 | K41: 0 | M41: 375
A42: فازة كريستال عسلي | B42: زجاج | C42: ذكريا | D42: 365 | E42: 0 | F42: 438 | G42: done | H42: 1 | I42: 1 | J42: 365 | K42: 789.61 | M42: 0
A43: شكل عاج كبير | B43: سيلفرات | C43: ذكريا | D43: 355 | E43: 2 | F43: 426 | G43: 45835 | H43: 2 | I43: 0 | J43: 710 | K43: 0 | M43: 710
A44: شيالة ازاز 3 | B44: سيلفرات | C44: شركة التقوى | D44: 350 | E44: 9 | F44: 420 | G44: 46100 | H44: 12 | I44: 3 | J44: 4200 | K44: 1300 | M44: 3150
A45: فازة بورسلين برجول كبيرة | B45: سيلفرات | C45: شركة الفرسان | D45: 350 | E45: 0 | F45: 420 | G45: 46097 | H45: 2 | I45: 2 | J45: 700 | K45: 800 | M45: 0
...

Sheet جرد 2026
A1: Product Name | B1: ItemType | C1: Supplier | D1: AvailableQty | E1: Cost price | F1: Toal Available | G1: Should be
A2: شجرة مانغوليا 80 سم | B2: =IF(A2="","",IFERROR(VLOOKUP(A2, Stock_New!A:M, 2, FALSE),"")) -> شجر صناعي | C2: =IF(A2="","",IFERROR(VLOOKUP(A2, Stock_New!A:M, 3, FALSE),"")) -> manufactured | D2: =3+2+1+1 -> 7 | E2: 90 | F2: =E2*D2 -> 630 | G2: =IF($A2="", "", IFERROR(VLOOKUP($A2, Stock_New!$A:$M, 5, FALSE), "")) -> 4
A3: شجرة مانغوليا 110 سم | B3: =IF(A3="","",IFERROR(VLOOKUP(A3, Stock_New!A:M, 2, FALSE),"")) -> شجر | C3: =IF(A3="","",IFERROR(VLOOKUP(A3, Stock_New!A:M, 3, FALSE),"")) -> manufactured | D3: =2+4+2+1+2 -> 11 | E3: 105 | F3: =E3*D3 -> 1155 | G3: =IF($A3="", "", IFERROR(VLOOKUP($A3, Stock_New!$A:$M, 5, FALSE), "")) -> 4
A4: شجرة مانغوليا 150 سم | B4: =IF(A4="","",IFERROR(VLOOKUP(A4, Stock_New!A:M, 2, FALSE),"")) -> شجر صناعي | C4: =IF(A4="","",IFERROR(VLOOKUP(A4, Stock_New!A:M, 3, FALSE),"")) -> manufactured | D4: 1 | E4: 130 | F4: =E4*D4 -> 130 | G4: =IF($A4="", "", IFERROR(VLOOKUP($A4, Stock_New!$A:$M, 5, FALSE), "")) -> 1
A5: شجرة بنجامين 80سم | B5: =IF(A5="","",IFERROR(VLOOKUP(A5, Stock_New!A:M, 2, FALSE),"")) -> شجر | C5: =IF(A5="","",IFERROR(VLOOKUP(A5, Stock_New!A:M, 3, FALSE),"")) -> manufactured | D5: =2+1+2+1+3+1+3+1 -> 14 | E5: =35+20+10 -> 65 | F5: =E5*D5 -> 910 | G5: =IF($A5="", "", IFERROR(VLOOKUP($A5, Stock_New!$A:$M, 5, FALSE), "")) -> 2
A6: شجرة بنجامين 110سم | B6: =IF(A6="","",IFERROR(VLOOKUP(A6, Stock_New!A:M, 2, FALSE),"")) -> بوكيه | C6: =IF(A6="","",IFERROR(VLOOKUP(A6, Stock_New!A:M, 3, FALSE),"")) -> manufactured | D6: =2+1+2+3 -> 8 | E6: =70+20+10 -> 100 | F6: =E6*D6 -> 800 | G6: =IF($A6="", "", IFERROR(VLOOKUP($A6, Stock_New!$A:$M, 5, FALSE), "")) -> 1
A7: شجرة خروع 80 سم | B7: شجر | C7: manufactured | D7: 1 | E7: =100+20+10 -> 130 | F7: =E7*D7 -> 130 | G7: =IF($A7="", "", IFERROR(VLOOKUP($A7, Stock_New!$A:$M, 5, FALSE), ""))
A8: شجرة ياسمين 80 سم مكثفة | B8: شجر | C8: manufactured | D8: 1 | E8: =3*90+20+10 -> 300 | F8: =E8*D8 -> 300 | G8: =IF($A8="", "", IFERROR(VLOOKUP($A8, Stock_New!$A:$M, 5, FALSE), ""))
A9: شجرة ياسمين 110سم | B9: =IF(A9="","",IFERROR(VLOOKUP(A9, Stock_New!A:M, 2, FALSE),"")) -> شجر | C9: =IF(A9="","",IFERROR(VLOOKUP(A9, Stock_New!A:M, 3, FALSE),"")) -> manufactured | D9: 1 | E9: =IF($A9="", "", IFERROR(VLOOKUP($A9, Stock_New!$A:$M, 4, FALSE), "")) -> 330 | F9: =E9*D9 -> 330 | G9: =IF($A9="", "", IFERROR(VLOOKUP($A9, Stock_New!$A:$M, 5, FALSE), "")) -> 1
A10: شجرة ياسمين 80سم | B10: =IF(A10="","",IFERROR(VLOOKUP(A10, Stock_New!A:M, 2, FALSE),"")) -> شجر | C10: =IF(A10="","",IFERROR(VLOOKUP(A10, Stock_New!A:M, 3, FALSE),"")) -> manufactured | D10: 1 | E10: =3*75+10+20 -> 255 | F10: =E10*D10 -> 255 | G10: =IF($A10="", "", IFERROR(VLOOKUP($A10, Stock_New!$A:$M, 5, FALSE), "")) -> 0
A11: شجرة مشمش فرعين | B11: =IF(A11="","",IFERROR(VLOOKUP(A11, Stock_New!A:M, 2, FALSE),"")) -> شجر | C11: =IF(A11="","",IFERROR(VLOOKUP(A11, Stock_New!A:M, 3, FALSE),"")) -> ذكريا | D11: =1+1+1 -> 3 | E11: =3*75+10+20 -> 255 | F11: =E11*D11 -> 765 | G11: =IF($A11="", "", IFERROR(VLOOKUP($A11, Stock_New!$A:$M, 5, FALSE), "")) -> 3
A12: بوت وسط فاضي | B12: =IF(A12="","",IFERROR(VLOOKUP(A12, Stock_New!A:M, 2, FALSE),"")) -> بوتات | C12: =IF(A12="","",IFERROR(VLOOKUP(A12, Stock_New!A:M, 3, FALSE),"")) -> عبدالفتاح | D12: =13+4+1+4+65+6+12+10+13+14 -> 142 | E12: =IF($A12="", "", IFERROR(VLOOKUP($A12, Stock_New!$A:$M, 4, FALSE), "")) -> 35 | F12: =E12*D12 -> 4970 | G12: =IF($A12="", "", IFERROR(VLOOKUP($A12, Stock_New!$A:$M, 5, FALSE), "")) -> 121
A13: شجرة نجمة جلد | B13: =IF(A13="","",IFERROR(VLOOKUP(A13, Stock_New!A:M, 2, FALSE),"")) -> شجر | C13: =IF(A13="","",IFERROR(VLOOKUP(A13, Stock_New!A:M, 3, FALSE),"")) -> شركة حسين علي | D13: =2+2 -> 4 | E13: =IF($A13="", "", IFERROR(VLOOKUP($A13, Stock_New!$A:$M, 4, FALSE), "")) -> 412.5 | F13: =E13*D13 -> 1650 | G13: =IF($A13="", "", IFERROR(VLOOKUP($A13, Stock_New!$A:$M, 5, FALSE), "")) -> 4
A14: شجرة جلد تركيب 18 عصفورة | B14: =IF(A14="","",IFERROR(VLOOKUP(A14, Stock_New!A:M, 2, FALSE),"")) -> شجر | C14: =IF(A14="","",IFERROR(VLOOKUP(A14, Stock_New!A:M, 3, FALSE),"")) -> شركة حسين علي | D14: =1+1 -> 2 | E14: =IF($A14="", "", IFERROR(VLOOKUP($A14, Stock_New!$A:$M, 4, FALSE), "")) -> 200 | F14: =E14*D14 -> 400 | G14: =IF($A14="", "", IFERROR(VLOOKUP($A14, Stock_New!$A:$M, 5, FALSE), "")) -> 2
A15: بوت جامبو طويل | B15: =IF(A15="","",IFERROR(VLOOKUP(A15, Stock_New!A:M, 2, FALSE),"")) -> بوتات | C15: =IF(A15="","",IFERROR(VLOOKUP(A15, Stock_New!A:M, 3, FALSE),"")) -> عبدالفتاح | D15: =2+2+5 -> 9 | E15: =IF($A15="", "", IFERROR(VLOOKUP($A15, Stock_New!$A:$M, 4, FALSE), "")) -> 175 | F15: =E15*D15 -> 1575 | G15: =IF($A15="", "", IFERROR(VLOOKUP($A15, Stock_New!$A:$M, 5, FALSE), "")) -> 9
A16: شجرة مشمش 4 فروع | B16: =IF(A16="","",IFERROR(VLOOKUP(A16, Stock_New!A:M, 2, FALSE),"")) -> شجر | C16: =IF(A16="","",IFERROR(VLOOKUP(A16, Stock_New!A:M, 3, FALSE),"")) -> ذكريا | D16: =2+1+3 -> 6 | E16: =IF($A16="", "", IFERROR(VLOOKUP($A16, Stock_New!$A:$M, 4, FALSE), "")) -> 275 | F16: =E16*D16 -> 1650 | G16: =IF($A16="", "", IFERROR(VLOOKUP($A16, Stock_New!$A:$M, 5, FALSE), "")) -> 4
A17: بوت كبير عادي | B17: =IF(A17="","",IFERROR(VLOOKUP(A17, Stock_New!A:M, 2, FALSE),"")) -> بوتات | C17: =IF(A17="","",IFERROR(VLOOKUP(A17, Stock_New!A:M, 3, FALSE),"")) -> ذكريا | D17: =2+1+1 -> 4 | E17: =IF($A17="", "", IFERROR(VLOOKUP($A17, Stock_New!$A:$M, 4, FALSE), "")) -> 135 | F17: =E17*D17 -> 540 | G17: =IF($A17="", "", IFERROR(VLOOKUP($A17, Stock_New!$A:$M, 5, FALSE), "")) -> 21
A18: شجرة موزة جلد 9 ورقة فردي 40×10 اسم | B18: =IF(A18="","",IFERROR(VLOOKUP(A18, Stock_New!A:M, 2, FALSE),"")) -> شجر | C18: =IF(A18="","",IFERROR(VLOOKUP(A18, Stock_New!A:M, 3, FALSE),"")) -> شركة الفرسان | D18: 1 | E18: =IF($A18="", "", IFERROR(VLOOKUP($A18, Stock_New!$A:$M, 4, FALSE), "")) -> 300 | F18: =E18*D18 -> 300 | G18: =IF($A18="", "", IFERROR(VLOOKUP($A18, Stock_New!$A:$M, 5, FALSE), "")) -> 0
A19: شجرة اريكا وسط | B19: =IF(A19="","",IFERROR(VLOOKUP(A19, Stock_New!A:M, 2, FALSE),"")) -> شجر | C19: =IF(A19="","",IFERROR(VLOOKUP(A19, Stock_New!A:M, 3, FALSE),"")) -> ذكريا | D19: 1 | E19: 565 | F19: =E19*D19 -> 565 | G19: =IF($A19="", "", IFERROR(VLOOKUP($A19, Stock_New!$A:$M, 5, FALSE), "")) -> 0
A20: بوت تركي كبير | B20: =IF(A20="","",IFERROR(VLOOKUP(A20, Stock_New!A:M, 2, FALSE),"")) -> بوتات | C20: =IF(A20="","",IFERROR(VLOOKUP(A20, Stock_New!A:M, 3, FALSE),"")) -> عبدالفتاح | D20: =2+5+1+17 -> 25 | E20: =IF($A20="", "", IFERROR(VLOOKUP($A20, Stock_New!$A:$M, 4, FALSE), "")) -> 65 | F20: =E20*D20 -> 1625 | G20: =IF($A20="", "", IFERROR(VLOOKUP($A20, Stock_New!$A:$M, 5, FALSE), "")) -> 13
A21: شجرة بلدي 48 | B21: =IF(A21="","",IFERROR(VLOOKUP(A21, Stock_New!A:M, 2, FALSE),"")) -> شجر | C21: =IF(A21="","",IFERROR(VLOOKUP(A21, Stock_New!A:M, 3, FALSE),"")) -> شركة حسين علي | D21: 2 | E21: =IF($A21="", "", IFERROR(VLOOKUP($A21, Stock_New!$A:$M, 4, FALSE), "")) -> 233.33 | F21: =E21*D21 -> 466.66 | G21: =IF($A21="", "", IFERROR(VLOOKUP($A21, Stock_New!$A:$M, 5, FALSE), "")) -> 2
A22: بوت وسط | B22: =IF(A22="","",IFERROR(VLOOKUP(A22, Stock_New!A:M, 2, FALSE),"")) -> بوتات | C22: =IF(A22="","",IFERROR(VLOOKUP(A22, Stock_New!A:M, 3, FALSE),"")) -> ذكريا | D22: =1+7 -> 8 | E22: 90 | F22: =E22*D22 -> 720 | G22: =IF($A22="", "", IFERROR(VLOOKUP($A22, Stock_New!$A:$M, 5, FALSE), "")) -> 17
A23: بوت طويل مستطيل فاضي | B23: =IF(A23="","",IFERROR(VLOOKUP(A23, Stock_New!A:M, 2, FALSE),"")) -> بوتات | C23: =IF(A23="","",IFERROR(VLOOKUP(A23, Stock_New!A:M, 3, FALSE),"")) -> ذكريا | D23: 3 | E23: =IF($A23="", "", IFERROR(VLOOKUP($A23, Stock_New!$A:$M, 4, FALSE), "")) -> 85 | F23: =E23*D23 -> 255 | G23: =IF($A23="", "", IFERROR(VLOOKUP($A23, Stock_New!$A:$M, 5, FALSE), "")) -> 3
A24: بوت تركي | B24: =IF(A24="","",IFERROR(VLOOKUP(A24, Stock_New!A:M, 2, FALSE),"")) -> بوتات | C24: =IF(A24="","",IFERROR(VLOOKUP(A24, Stock_New!A:M, 3, FALSE),"")) -> ذكريا | D24: =1+1+1 -> 3 | E24: =IF($A24="", "", IFERROR(VLOOKUP($A24, Stock_New!$A:$M, 4, FALSE), "")) -> 105 | F24: =E24*D24 -> 315 | G24: =IF($A24="", "", IFERROR(VLOOKUP($A24, Stock_New!$A:$M, 5, FALSE), "")) -> 2
A25: شجرة جاهزة | B25: =IF(A25="","",IFERROR(VLOOKUP(A25, Stock_New!A:M, 2, FALSE),"")) -> شجر | C25: =IF(A25="","",IFERROR(VLOOKUP(A25, Stock_New!A:M, 3, FALSE),"")) -> ذكريا | D25: =2+2+6 -> 10 | E25: =IF($A25="", "", IFERROR(VLOOKUP($A25, Stock_New!$A:$M, 4, FALSE), "")) -> 84 | F25: =E25*D25 -> 840 | G25: =IF($A25="", "", IFERROR(VLOOKUP($A25, Stock_New!$A:$M, 5, FALSE), "")) -> 16
A26: جلد تركيب 12 | B26: =IF(A26="","",IFERROR(VLOOKUP(A26, Stock_New!A:M, 2, FALSE),"")) -> شجر | C26: =IF(A26="","",IFERROR(VLOOKUP(A26, Stock_New!A:M, 3, FALSE),"")) -> شركة حسين علي | D26: 7 | E26: =IF($A26="", "", IFERROR(VLOOKUP($A26, Stock_New!$A:$M, 4, FALSE), "")) -> 85 | F26: =E26*D26 -> 595 | G26: =IF($A26="", "", IFERROR(VLOOKUP($A26, Stock_New!$A:$M, 5, FALSE), "")) -> 6
A27: شجرة تركيب 18 ورقة موزة | B27: =IF(A27="","",IFERROR(VLOOKUP(A27, Stock_New!A:M, 2, FALSE),"")) -> شجر | C27: =IF(A27="","",IFERROR(VLOOKUP(A27, Stock_New!A:M, 3, FALSE),"")) -> عبدالفتاح | D27: =1+4 -> 5 | E27: =IF($A27="", "", IFERROR(VLOOKUP($A27, Stock_New!$A:$M, 4, FALSE), "")) -> 120 | F27: =E27*D27 -> 600 | G27: =IF($A27="", "", IFERROR(VLOOKUP($A27, Stock_New!$A:$M, 5, FALSE), "")) -> 7
A28: عباد 12 فرع SF-171 | B28: =IF(A28="","",IFERROR(VLOOKUP(A28, Stock_New!A:M, 2, FALSE),"")) -> ورد لوحدة | C28: =IF(A28="","",IFERROR(VLOOKUP(A28, Stock_New!A:M, 3, FALSE),"")) -> شركة الفرسان | D28: 4 | E28: =IF($A28="", "", IFERROR(VLOOKUP($A28, Stock_New!$A:$M, 4, FALSE), "")) -> 175 | F28: =E28*D28 -> 700 | G28: =IF($A28="", "", IFERROR(VLOOKUP($A28, Stock_New!$A:$M, 5, FALSE), "")) -> 4
A29: طحالب أبيض فرسان | B29: =IF(A29="","",IFERROR(VLOOKUP(A29, Stock_New!A:M, 2, FALSE),"")) -> ورد لوحدة | C29: =IF(A29="","",IFERROR(VLOOKUP(A29, Stock_New!A:M, 3, FALSE),"")) -> شركة الفرسان | D29: =3/5+2 -> 2.6 | E29: =IF($A29="", "", IFERROR(VLOOKUP($A29, Stock_New!$A:$M, 4, FALSE), "")) -> 50 | F29: =E29*D29 -> 130 | G29: =IF($A29="", "", IFERROR(VLOOKUP($A29, Stock_New!$A:$M, 5, FALSE), "")) -> 3
A30: بلدي 12 فرسان | B30: =IF(A30="","",IFERROR(VLOOKUP(A30, Stock_New!A:M, 2, FALSE),"")) -> ورد لوحدة | C30: =IF(A30="","",IFERROR(VLOOKUP(A30, Stock_New!A:M, 3, FALSE),"")) -> شركة الفرسان | D30: =1+3+1+2/12 -> 5.1666667 | E30: =IF($A30="", "", IFERROR(VLOOKUP($A30, Stock_New!$A:$M, 4, FALSE), "")) -> 85 | F30: =E30*D30 -> 439.16667 | G30: =IF($A30="", "", IFERROR(VLOOKUP($A30, Stock_New!$A:$M, 5, FALSE), "")) -> 4.3333333
A31: افرع طويلة | B31: =IF(A31="","",IFERROR(VLOOKUP(A31, Stock_New!A:M, 2, FALSE),"")) -> ورد لوحده | C31: =IF(A31="","",IFERROR(VLOOKUP(A31, Stock_New!A:M, 3, FALSE),"")) -> ذكريا | D31: =1+5+3+14 -> 23 | E31: =IF($A31="", "", IFERROR(VLOOKUP($A31, Stock_New!$A:$M, 4, FALSE), "")) -> 75 | F31: =E31*D31 -> 1725 | G31: =IF($A31="", "", IFERROR(VLOOKUP($A31, Stock_New!$A:$M, 5, FALSE), "")) -> 29
A32: بلدي 24 | B32: =IF(A32="","",IFERROR(VLOOKUP(A32, Stock_New!A:M, 2, FALSE),"")) -> ورد لحدة | C32: =IF(A32="","",IFERROR(VLOOKUP(A32, Stock_New!A:M, 3, FALSE),"")) -> شركة حسين علي | D32: =1+5 -> 6 | E32: =IF($A32="", "", IFERROR(VLOOKUP($A32, Stock_New!$A:$M, 4, FALSE), "")) -> 175 | F32: =E32*D32 -> 1050 | G32: =IF($A32="", "", IFERROR(VLOOKUP($A32, Stock_New!$A:$M, 5, FALSE), "")) -> 6
A33: توليب 24 حسين علي | B33: =IF(A33="","",IFERROR(VLOOKUP(A33, Stock_New!A:M, 2, FALSE),"")) -> ورد لحدة | C33: =IF(A33="","",IFERROR(VLOOKUP(A33, Stock_New!A:M, 3, FALSE),"")) -> شركة حسين علي | D33: 2 | E33: =IF($A33="", "", IFERROR(VLOOKUP($A33, Stock_New!$A:$M, 4, FALSE), "")) -> 150 | F33: =E33*D33 -> 300 | G33: =IF($A33="", "", IFERROR(VLOOKUP($A33, Stock_New!$A:$M, 5, FALSE), "")) -> 7
A34: ريشة دوناتس | B34: =IF(A34="","",IFERROR(VLOOKUP(A34, Stock_New!A:M, 2, FALSE),"")) -> ريش | C34: =IF(A34="","",IFERROR(VLOOKUP(A34, Stock_New!A:M, 3, FALSE),"")) -> شركة حسين علي | D34: =6+1+1+30+9+2 -> 49 | E34: =IF($A34="", "", IFERROR(VLOOKUP($A34, Stock_New!$A:$M, 4, FALSE), "")) -> 15 | F34: =E34*D34 -> 735 | G34: =IF($A34="", "", IFERROR(VLOOKUP($A34, Stock_New!$A:$M, 5, FALSE), "")) -> 52
A35: بوكيه ورد نوعين | B35: =IF(A35="","",IFERROR(VLOOKUP(A35, Stock_New!A:M, 2, FALSE),"")) -> ورد لوحده | C35: =IF(A35="","",IFERROR(VLOOKUP(A35, Stock_New!A:M, 3, FALSE),"")) -> ذكريا | D35: 1 | E35: =IF($A35="", "", IFERROR(VLOOKUP($A35, Stock_New!$A:$M, 4, FALSE), "")) -> 145 | F35: =E35*D35 -> 145 | G35: =IF($A35="", "", IFERROR(VLOOKUP($A35, Stock_New!$A:$M, 5, FALSE), "")) -> 0
A36: بوكيه ابيض | B36: =IF(A36="","",IFERROR(VLOOKUP(A36, Stock_New!A:M, 2, FALSE),"")) -> ورد لوحده | C36: =IF(A36="","",IFERROR(VLOOKUP(A36, Stock_New!A:M, 3, FALSE),"")) -> ذكريا | D36: 1 | E36: =IF($A36="", "", IFERROR(VLOOKUP($A36, Stock_New!$A:$M, 4, FALSE), "")) -> 145 | F36: =E36*D36 -> 145 | G36: =IF($A36="", "", IFERROR(VLOOKUP($A36, Stock_New!$A:$M, 5, FALSE), "")) -> 0
A37: بوكيه بلاسيتك وورد مسك الليل | B37: =IF(A37="","",IFERROR(VLOOKUP(A37, Stock_New!A:M, 2, FALSE),"")) -> بوكيه | C37: =IF(A37="","",IFERROR(VLOOKUP(A37, Stock_New!A:M, 3, FALSE),"")) -> ذكريا | D37: 1 | E37: =IF($A37="", "", IFERROR(VLOOKUP($A37, Stock_New!$A:$M, 4, FALSE), "")) -> 112.5 | F37: =E37*D37 -> 112.5 | G37: =IF($A37="", "", IFERROR(VLOOKUP($A37, Stock_New!$A:$M, 5, FALSE), "")) -> 1
A38: بوكيه بلاستيك ورد مقفول وورد صغير | B38: =IF(A38="","",IFERROR(VLOOKUP(A38, Stock_New!A:M, 2, FALSE),"")) -> بوكيه | C38: =IF(A38="","",IFERROR(VLOOKUP(A38, Stock_New!A:M, 3, FALSE),"")) -> ذكريا | D38: 2 | E38: =IF($A38="", "", IFERROR(VLOOKUP($A38, Stock_New!$A:$M, 4, FALSE), "")) -> 160 | F38: =E38*D38 -> 320 | G38: =IF($A38="", "", IFERROR(VLOOKUP($A38, Stock_New!$A:$M, 5, FALSE), "")) -> 0
A39: بوكيه ريش حمام | B39: =IF(A39="","",IFERROR(VLOOKUP(A39, Stock_New!A:M, 2, FALSE),"")) -> بوكيه | C39: =IF(A39="","",IFERROR(VLOOKUP(A39, Stock_New!A:M, 3, FALSE),"")) -> ذكريا | D39: 1 | E39: =IF($A39="", "", IFERROR(VLOOKUP($A39, Stock_New!$A:$M, 4, FALSE), "")) -> 135 | F39: =E39*D39 -> 135 | G39: =IF($A39="", "", IFERROR(VLOOKUP($A39, Stock_New!$A:$M, 5, FALSE), "")) -> 2
A40: بوكيه بلاستيك وبوكيه اخضر | B40: =IF(A40="","",IFERROR(VLOOKUP(A40, Stock_New!A:M, 2, FALSE),"")) -> بوكيه | C40: =IF(A40="","",IFERROR(VLOOKUP(A40, Stock_New!A:M, 3, FALSE),"")) -> ذكريا | D40: 2 | E40: =IF($A40="", "", IFERROR(VLOOKUP($A40, Stock_New!$A:$M, 4, FALSE), "")) -> 140 | F40: =E40*D40 -> 280 | G40: =IF($A40="", "", IFERROR(VLOOKUP($A40, Stock_New!$A:$M, 5, FALSE), "")) -> 2
...

Sheet الورقة13
A1: راس مال | B1: -350503
A2: راتب | B2: =24153 -> 24153
A3: ايجار وتامين | B3: =37800 -> 37800
A4: تاسيس | B4: 64000
A5: اجمالي قيمة الجر | B5: =sum('جرد 2026'!F:F)+12000+18240+8680+2000+16050 -> 236155.62
B6: =SUM(B1:B5) -> 11605.619 | C6: =16500+10000+1700+12000 -> 40200
D7: =B5+C6 -> 276355.62
A10: الناتج | C10: =B6-D7 -> -264750

Sheet Orders_New
A1: ItemName | B1: ItemType | C1: Qty | D1: PurchasePrice | E1: Supplier | F1: OrderDate | G1: Status | H1: OrderID | I1: EnteredBy | J1: Notes
A2: فازة ازاز كبيره وبوكيه | B2: بوكيه | C2: 1 | D2: 725 | E2: ذكريا | F2: 45812 | G2: done | H2: ORD-1765058110612-119
A3: طقم زجاج ابيض وريش وورد صغير | B3: بوكيه | C3: 1 | D3: 415 | E3: ذكريا | F3: 45812 | G3: done | H3: ORD-1765058110618-468
A4: طقم زجاج ابيض وبوكيه اخضر | B4: بوكيه | C4: 1 | D4: 325 | E4: ذكريا | F4: 45812 | G4: done | H4: ORD-1765058110625-839
A5: طقم زجاج ابيض وريش بس | B5: بوكيه | C5: 1 | D5: 300 | E5: ذكريا | F5: 45812 | G5: done | H5: ORD-1765058110631-241
A6: فازة ازاز وبوكيه ورد غالي | B6: بوكيه زجاج | C6: 2 | D6: 295 | E6: ذكريا | F6: 45812 | G6: done | H6: ORD-1765058110639-611
A7: فازة ازاز وبوكيه ابيض وبيبي فلاور | B7: بوكيه زجاج | C7: 1 | D7: 200 | E7: ذكريا | F7: 45812 | G7: done | H7: ORD-1765058110644-364
A8: فازة خزف وبوكيه ابيض كبير | B8: بوكيه | C8: 1 | D8: 185 | E8: ذكريا | F8: 45812 | G8: done | H8: ORD-1765058110663-808
A9: فازة خزف وبوكيه ورد مقفول وورد صغير | B9: بوكيه | C9: 2 | D9: 180 | E9: ذكريا | F9: 45812 | G9: done | H9: ORD-1765058110669-489
A10: فازة ازاز وبوكيه | B10: بوكيه | C10: 3 | D10: 180 | E10: ذكريا | F10: 45812 | G10: done | H10: ORD-1765058110675-912
A11: بوكيه بلاستيك ورد كبير | B11: بوكيه | C11: 1 | D11: 175 | E11: ذكريا | F11: 45812 | G11: done | H11: ORD-1765058110681-293
A12: فازة خزف كبيره مشمش | B12: بوكيه | C12: 4 | D12: 175 | E12: ذكريا | F12: 45812 | G12: done | H12: ORD-1765058110687-965
A13: بوكيه بلاستيك | B13: بوكيه | C13: 2 | D13: 160 | E13: ذكريا | F13: 45812 | G13: done | H13: ORD-1765058110692-472
... A20: فازة خزف وبوكيه ورد مقفول | B20: بوكيه | C20: 3 | D20: 125 | E20: ذكريا | F20: 45812 | G20: done | H20: ORD-1765058110737-508
A21: بوكيه خزف مقسوم ورد شبه التاج | B21: بوكيه | C21: 2 | D21: =225/2 -> 112.5 | E21: ذكريا | F21: 45812 | G21: done | H21: ORD-1765058110743-574
A22: طقم زجاج ابيض فاضي | B22: زجاج ابيض | C22: 1 | D22: 125 | E22: ذكريا | F22: 45812 | G22: done | H22: ORD-1765058110749-731
A23: طقم دوناتس | B23: خزف | C23: 3 | D23: 135 | E23: ذكريا | F23: 45812 | G23: done | H23: ORD-1765058110758-650
A24: قطعة دوناتس | B24: خزف | C24: 2 | D24: =135/3 -> 45 | E24: ذكريا | F24: 45812 | G24: done | H24: ORD-1765058110764-606
A25: مزرعة بورسلين | B25: بوكيه | C25: 1 | D25: 55 | E25: ذكريا | F25: 45812 | G25: done | H25: ORD-1765058110769-292
A26: مزرعة بورسلين | B26: بوكيه | C26: 9 | D26: 35 | E26: ذكريا | F26: 45812 | G26: done | H26: ORD-1765058110788-263
A27: بوكيه اخضر | B27: ورد لوحده | C27: 2 | D27: 175 | E27: ذكريا | F27: 45812 | G27: done | H27: ORD-1765058110793-854
A28: طقم باسكت | B28: سيلفرات | C28: 1 | D28: 755 | E28: ذكريا | F28: 45812 | G28: done | H28: ORD-1765058110799-949
A29: شمعدان نخلة | B29: سيلفرات | C29: 1 | D29: 625 | E29: ذكريا | F29: 45812 | G29: done | H29: ORD-1765058110804-393
A30: شمعدان كريستال | B30: سيلفرات | C30: 1 | D30: 595 | E30: ذكريا | F30: 45812 | G30: done | H30: ORD-1765058110810-328
A31: شوكة كبيرة | B31: سيلفرات | C31: 3 | D31: 220 | E31: ذكريا | F31: 45812 | G31: done | H31: ORD-1765058110816-819
A32: شوكة وسط | B32: سيلفرات | C32: 6 | D32: 155 | E32: ذكريا | F32: 45812 | G32: done | H32: ORD-1765058110822-671
A33: شوكة صغيرة | B33: سيلفرات | C33: 6 | D33: 130 | E33: ذكريا | F33: 45812 | G33: done | H33: ORD-1765058110828-852
A34: شمعدان رفيع طويل عادي | B34: سيلفرات | C34: 2 | D34: 205 | E34: ذكريا | F34: 45812 | G34: done | H34: ORD-1765058110834-694
A35: شمعدان رفيع طويل اسود | B35: سيلفرات | C35: 2 | D35: 215 | E35: ذكريا | F35: 45812 | G35: done | H35: ORD-1765058110840-835
A36: كريستالة ديكور | B36: سيلفرات | C36: 3 | D36: 175 | E36: ذكريا | F36: 45812 | G36: done | H36: ORD-1765058110846-535
... A108: بوكيه بلاستيك واتنين صغيرين | B108: بوكيه | C108: 1 | D108: 125 | E108: ذكريا | F108: 45835 | G108: done | H108: ORD-1765058111377-814
A109: بوكيه بلاسيتك وورد مسك الليل | B109: بوكيه | C109: 2 | D109: =225/2 -> 112.5 | E109: ذكريا | F109: 45835 | G109: done | H109: ORD-1765058111383-847
A110: بوكيه ريش وورد صغير | B110: بوكيه | C110: 1 | D110: 110 | E110: ذكريا | F110: 45835 | G110: done | H110: ORD-1765058111389-358
A111: بوكيه بلاسيتك وورد احمر صغير | B111: بوكيه | C111: 1 | D111: 110 | E111: ذكريا | F111: 45835 | G111: done | H111: ORD-1765058111394-179
A112: بوكيه بلاستيك وورد روز | B112: بوكيه | C112: 1 | D112: 110 | E112: ذكريا | F112: 45835 | G112: done | H112: ORD-1765058111399-739
A113: بوكيه بلاستيك وورد مقفول | B113: بوكيه | C113: 2 | D113: 110 | E113: ذكريا | F113: 45835 | G113: done | H113: ORD-1765058111404-618
A114: مزرعة | B114: بوكيه | C114: 32 | D114: 35 | E114: ذكريا | F114: 45835 | G114: done | H114: ORD-1765058111409-193
A115: مزرعة صغيرة اكليرك | B115: بوكيه | C115: 16 | D115: 30 | E115: ذكريا | F115: 45835 | G115: done | H115: ORD-1765058111414-458
A116: اشكال السيرفرات | B116: سيلفرات | C116: 13 | D116: 120 | E116: ذكريا | F116: 45845 | G116: done | H116: ORD-1765058111419-420
A117: اشكال سيلفرات اقل | B117: سيلفرات | C117: 2 | D117: 95 | E117: ذكريا | F117: 45845 | G117: done | H117: ORD-1765058111424-533
...

Sheet Sales_New
A1: ProductName | B1: ItemType | C1: Qty | D1: Supplier | E1: SuggestedPrice | F1: ActualUnitPrice | G1: Discount | H1: TotalSale | I1: SaleDate | J1: Status | K1: SaleID | L1: EnteredBy | M1: اسم العميل | N1: الباقي | O1: تم دفع | P1: التكلفة
A2: بوت تركي | B2: =IF(A2="","",IFERROR(VLOOKUP(A2, Stock_New!A:M, 2, FALSE),"")) -> بوتات | C2: 2 | D2: =IF(A2="","",IFERROR(VLOOKUP(A2, Stock_New!A:M, 3, FALSE),"")) -> ذكريا | E2: =IF($A2="", "", IFERROR(VLOOKUP($A2, Stock_New!$A:$M, 6, FALSE), "")) -> 126 | F2: 120 | H2: 240 | I2: done | J2: done | K2: SAL-1765059347259-242 | M2: عم خالد | N2: =550-200-350 -> 0
A3: شجرة تركيب 12 ورقة | B3: =IF(A3="","",IFERROR(VLOOKUP(A3, Stock_New!A:M, 2, FALSE),"")) -> شجر | C3: 2 | D3: =IF(A3="","",IFERROR(VLOOKUP(A3, Stock_New!A:M, 3, FALSE),"")) -> ذكريا | E3: =IF($A3="", "", IFERROR(VLOOKUP($A3, Stock_New!$A:$M, 6, FALSE), "")) -> 114 | F3: 75 | G3: 0 | H3: 150 | I3: done | J3: done | K3: SAL-1765059347287-676 | M3: عم خالد | N3: =550-200-350 -> 0
A4: بوكيه خزف | B4: =IF(A4="","",IFERROR(VLOOKUP(A4, Stock_New!A:M, 2, FALSE),"")) -> بوكيه | C4: 1 | D4: =IF(A4="","",IFERROR(VLOOKUP(A4, Stock_New!A:M, 3, FALSE),"")) -> ذكريا | E4: =IF($A4="", "", IFERROR(VLOOKUP($A4, Stock_New!$A:$M, 6, FALSE), "")) -> 168 | F4: 150 | G4: 0 | H4: 150 | I4: done | J4: done | K4: SAL-1765059347322-954 | M4: عم خالد | N4: =550-200-350 -> 0
A5: فازة خزف وورد احمر صغير | B5: =IF(A5="","",IFERROR(VLOOKUP(A5, Stock_New!A:M, 2, FALSE),"")) -> بوكيه | C5: 1 | D5: =IF(A5="","",IFERROR(VLOOKUP(A5, Stock_New!A:M, 3, FALSE),"")) -> ذكريا | E5: =IF($A5="", "", IFERROR(VLOOKUP($A5, Stock_New!$A:$M, 6, FALSE), "")) -> 162 | F5: 195 | G5: 0 | H5: 195 | I5: done | J5: done | K5: SAL-1765059347355-448 | M5: عم خالد | N5: =550-200-350 -> 0
A6: فازة خزف وبوكيه ابيض كبير | B6: =IF(A6="","",IFERROR(VLOOKUP(A6, Stock_New!A:M, 2, FALSE),"")) -> بوكيه | C6: 1 | D6: =IF(A6="","",IFERROR(VLOOKUP(A6, Stock_New!A:M, 3, FALSE),"")) -> ذكريا | E6: =IF($A6="", "", IFERROR(VLOOKUP($A6, Stock_New!$A:$M, 6, FALSE), "")) -> 222 | F6: 235 | G6: 0 | H6: 235 | I6: done | J6: done | K6: SAL-1765059347379-326
A7: مزرعة | B7: =IF(A7="","",IFERROR(VLOOKUP(A7, Stock_New!A:M, 2, FALSE),"")) -> بوكيه | C7: 2 | D7: =IF(A7="","",IFERROR(VLOOKUP(A7, Stock_New!A:M, 3, FALSE),"")) -> ذكريا | E7: =IF($A7="", "", IFERROR(VLOOKUP($A7, Stock_New!$A:$M, 6, FALSE), "")) -> 44.4 | F7: 50 | G7: 0 | H7: 100 | I7: done | J7: done | K7: SAL-1765059347412-273
A8: شجرة ورق عريض | B8: =IF(A8="","",IFERROR(VLOOKUP(A8, Stock_New!A:M, 2, FALSE),"")) -> شجر | C8: 1 | D8: =IF(A8="","",IFERROR(VLOOKUP(A8, Stock_New!A:M, 3, FALSE),"")) -> ذكريا | E8: =IF($A8="", "", IFERROR(VLOOKUP($A8, Stock_New!$A:$M, 6, FALSE), "")) -> 234 | F8: 245 | G8: 0 | H8: 245 | I8: done | J8: done | K8: SAL-1765059347444-973
A9: بوكيه ورد احمر صغير واخضر | B9: =IF(A9="","",IFERROR(VLOOKUP(A9, Stock_New!A:M, 2, FALSE),"")) -> بوكيه | C9: 1 | D9: =IF(A9="","",IFERROR(VLOOKUP(A9, Stock_New!A:M, 3, FALSE),"")) -> ذكريا | E9: =IF($A9="", "", IFERROR(VLOOKUP($A9, Stock_New!$A:$M, 6, FALSE), "")) -> 204 | F9: 220 | G9: 0 | H9: 220 | I9: done | J9: done | K9: SAL-1765059347473-514
A10: مج بشاليموه | B10: =IF(A10="","",IFERROR(VLOOKUP(A10, Stock_New!A:M, 2, FALSE),"")) -> مطبخ | C10: 2 | D10: =IF(A10="","",IFERROR(VLOOKUP(A10, Stock_New!A:M, 3, FALSE),"")) -> ذكريا | E10: =IF($A10="", "", IFERROR(VLOOKUP($A10, Stock_New!$A:$M, 6, FALSE), "")) -> 90 | F10: 100 | G10: 0 | H10: 200 | I10: done | J10: done | K10: SAL-1765059347499-157 | M10: عم سعد
A11: فازة خزف وورد احمر صغير | B11: =IF(A11="","",IFERROR(VLOOKUP(A11, Stock_New!A:M, 2, FALSE),"")) -> بوكيه | C11: 1 | D11: =IF(A11="","",IFERROR(VLOOKUP(A11, Stock_New!A:M, 3, FALSE),"")) -> ذكريا | E11: =IF($A11="", "", IFERROR(VLOOKUP($A11, Stock_New!$A:$M, 6, FALSE), "")) -> 162 | F11: 195 | G11: 0 | H11: 195 | I11: done | J11: done | K11: SAL-1765059347533-739 | M11: عم سعد
A12: اشكال السيرفرات | B12: =IF(A12="","",IFERROR(VLOOKUP(A12, Stock_New!A:M, 2, FALSE),"")) -> سيلفرات | C12: 1 | D12: =IF(A12="","",IFERROR(VLOOKUP(A12, Stock_New!A:M, 3, FALSE),"")) -> ذكريا | E12: =IF($A12="", "", IFERROR(VLOOKUP($A12, Stock_New!$A:$M, 6, FALSE), "")) -> 144 | F12: 180 | G12: 0 | H12: 180 | I12: done | J12: done | K12: SAL-1765059347558-695 | M12: عم سعد
A13: بوت تركي | B13: =IF(A13="","",IFERROR(VLOOKUP(A13, Stock_New!A:M, 2, FALSE),"")) -> بوتات | C13: 1 | D13: =IF(A13="","",IFERROR(VLOOKUP(A13, Stock_New!A:M, 3, FALSE),"")) -> ذكريا | E13: =IF($A13="", "", IFERROR(VLOOKUP($A13, Stock_New!$A:$M, 6, FALSE), "")) -> 126 | F13: 140 | G13: 0 | H13: 140 | I13: done | J13: done | K13: SAL-1765059347584-687 | M13: عم سعد
A14: مبخرة غزالة | B14: =IF(A14="","",IFERROR(VLOOKUP(A14, Stock_New!A:M, 2, FALSE),"")) -> خزف | C14: 1 | D14: =IF(A14="","",IFERROR(VLOOKUP(A14, Stock_New!A:M, 3, FALSE),"")) -> ذكريا | E14: =IF($A14="", "", IFERROR(VLOOKUP($A14, Stock_New!$A:$M, 6, FALSE), "")) -> 72 | F14: 120 | G14: 0 | H14: 120 | I14: done | J14: done | K14: SAL-1765059347616-473 | M14: عم سعد
A15: مزرعة | B15: =IF(A15="","",IFERROR(VLOOKUP(A15, Stock_New!A:M, 2, FALSE),"")) -> بوكيه | C15: 3 | D15: =IF(A15="","",IFERROR(VLOOKUP(A15, Stock_New!A:M, 3, FALSE),"")) -> ذكريا | E15: =IF($A15="", "", IFERROR(VLOOKUP($A15, Stock_New!$A:$M, 6, FALSE), "")) -> 44.4 | F15: 50 | G15: 0 | H15: 150 | I15: done | J15: done | K15: SAL-1765059347643-179 | M15: محمد حامد التمساح
A16: بوكيه بلاستيك وورد احمر | B16: =IF(A16="","",IFERROR(VLOOKUP(A16, Stock_New!A:M, 2, FALSE),"")) -> بوكيه | C16: 1 | D16: =IF(A16="","",IFERROR(VLOOKUP(A16, Stock_New!A:M, 3, FALSE),"")) -> ذكريا | E16: =IF($A16="", "", IFERROR(VLOOKUP($A16, Stock_New!$A:$M, 6, FALSE), "")) -> 264 | F16: 252 | G16: 0 | H16: 252 | I16: done | J16: done | K16: SAL-1765059347675-928 | M16: محمد حامد التمساح
A17: بوكيه بلاستيك ورد كبير | B17: =IF(A17="","",IFERROR(VLOOKUP(A17, Stock_New!A:M, 2, FALSE),"")) -> بوكيه | C17: 1 | D17: =IF(A17="","",IFERROR(VLOOKUP(A17, Stock_New!A:M, 3, FALSE),"")) -> ذكريا | E17: =IF($A17="", "", IFERROR(VLOOKUP($A17, Stock_New!$A:$M, 6, FALSE), "")) -> 210 | F17: 290 | G17: 0 | H17: 290 | I17: done | J17: done | K17: SAL-1765059347709-743 | M17: محمد حامد التمساح
A18: بوكيه بلاستيك ورد مقفول وورد صغير | B18: =IF(A18="","",IFERROR(VLOOKUP(A18, Stock_New!A:M, 2, FALSE),"")) -> بوكيه | C18: 1 | D18: =IF(A18="","",IFERROR(VLOOKUP(A18, Stock_New!A:M, 3, FALSE),"")) -> ذكريا | E18: =IF($A18="", "", IFERROR(VLOOKUP($A18, Stock_New!$A:$M, 6, FALSE), "")) -> 192 | F18: 233 | G18: 0 | H18: 233 | I18: done | J18: done | K18: SAL-1765059347739-667 | M18: محمد حامد التمساح
A19: فازة خزف وورد احمر صغير | B19: =IF(A19="","",IFERROR(VLOOKUP(A19, Stock_New!A:M, 2, FALSE),"")) -> بوكيه | C19: 2 | D19: =IF(A19="","",IFERROR(VLOOKUP(A19, Stock_New!A:M, 3, FALSE),"")) -> ذكريا | E19: =IF($A19="", "", IFERROR(VLOOKUP($A19, Stock_New!$A:$M, 6, FALSE), "")) -> 162 | F19: 180 | G19: 0 | H19: =(1-Sales_New!$G19)*Sales_New!$F19*Sales_New!$C19 -> 360 | I19: done | J19: insufficient | M19: محمد حامد التمساح
A20: كريستالة ديكور | B20: =IF(A20="","",IFERROR(VLOOKUP(A20, Stock_New!A:M, 2, FALSE),"")) -> سيلفرات | C20: 1 | D20: =IF(A20="","",IFERROR(VLOOKUP(A20, Stock_New!A:M, 3, FALSE),"")) -> ذكريا | E20: =IF($A20="", "", IFERROR(VLOOKUP($A20, Stock_New!$A:$M, 6, FALSE), "")) -> 210 | F20: 220 | G20: 0 | H20: 220 | I20: done | J20: done | K20: SAL-1765059347778-898 | M20: محمد حامد التمساح
A21: مزرعة | B21: =IF(A21="","",IFERROR(VLOOKUP(A21, Stock_New!A:M, 2, FALSE),"")) -> بوكيه | C21: 1 | D21: =IF(A21="","",IFERROR(VLOOKUP(A21, Stock_New!A:M, 3, FALSE),"")) -> ذكريا | E21: =IF($A21="", "", IFERROR(VLOOKUP($A21, Stock_New!$A:$M, 6, FALSE), "")) -> 44.4 | F21: 50 | G21: 0 | H21: 50 | I21: done | J21: done | K21: SAL-1765059347812-969 | M21: زبون
A22: مج بشاليموه | B22: =IF(A22="","",IFERROR(VLOOKUP(A22, Stock_New!A:M, 2, FALSE),"")) -> مطبخ | C22: 1 | D22: =IF(A22="","",IFERROR(VLOOKUP(A22, Stock_New!A:M, 3, FALSE),"")) -> ذكريا | E22: =IF($A22="", "", IFERROR(VLOOKUP($A22, Stock_New!$A:$M, 6, FALSE), "")) -> 90 | F22: 100 | G22: 0 | H22: 100 | I22: done | J22: done | K22: SAL-1765059347851-686 | M22: زبون
A23: شجرة ورق عريض قماش | B23: =IF(A23="","",IFERROR(VLOOKUP(A23, Stock_New!A:M, 2, FALSE),"")) -> شجر | C23: 2 | D23: =IF(A23="","",IFERROR(VLOOKUP(A23, Stock_New!A:M, 3, FALSE),"")) -> ذكريا | E23: =IF($A23="", "", IFERROR(VLOOKUP($A23, Stock_New!$A:$M, 6, FALSE), "")) -> 227.15 | F23: 245 | G23: 0 | H23: 490 | I23: done | J23: done | K23: SAL-1765059762383-965 | M23: زبون
A24: بوت تركي | B24: =IF(A24="","",IFERROR(VLOOKUP(A24, Stock_New!A:M, 2, FALSE),"")) -> بوتات | C24: 2 | D24: =IF(A24="","",IFERROR(VLOOKUP(A24, Stock_New!A:M, 3, FALSE),"")) -> ذكريا | E24: =IF($A24="", "", IFERROR(VLOOKUP($A24, Stock_New!$A:$M, 6, FALSE), "")) -> 126 | F24: 135 | G24: 0 | H24: 270 | I24: done | J24: done | K24: SAL-1765059347894-950 | M24: زبون
A25: مزرعة | B25: =IF(A25="","",IFERROR(VLOOKUP(A25, Stock_New!A:M, 2, FALSE),"")) -> بوكيه | C25: 2 | D25: =IF(A25="","",IFERROR(VLOOKUP(A25, Stock_New!A:M, 3, FALSE),"")) -> ذكريا | E25: =IF($A25="", "", IFERROR(VLOOKUP($A25, Stock_New!$A:$M, 6, FALSE), "")) -> 44.4 | F25: 50 | G25: 0 | H25: 100 | I25: done | J25: done | K25: SAL-1765059347922-722 | M25: فاطمة اخت ايمان
A26: مزرعة | B26: =IF(A26="","",IFERROR(VLOOKUP(A26, Stock_New!A:M, 2, FALSE),"")) -> بوكيه | C26: 3 | D26: =IF(A26="","",IFERROR(VLOOKUP(A26, Stock_New!A:M, 3, FALSE),"")) -> ذكريا | E26: =IF($A26="", "", IFERROR(VLOOKUP($A26, Stock_New!$A:$M, 6, FALSE), "")) -> 44.4 | F26: 50 | G26: 0 | H26: 150 | I26: done | J26: done | K26: SAL-1765059347947-317 | M26: زبون
A27: بوكيه بلاستيك و ورد بني وصغير | B27: =IF(A27="","",IFERROR(VLOOKUP(A27, Stock_New!A:M, 2, FALSE),"")) -> بوكيه | C27: 1 | D27: =IF(A27="","",IFERROR(VLOOKUP(A27, Stock_New!A:M, 3, FALSE),"")) -> ذكريا | E27: =IF($A27="", "", IFERROR(VLOOKUP($A27, Stock_New!$A:$M, 6, FALSE), "")) -> 162 | F27: 250 | G27: 0.1 | H27: 249.75 | I27: done | J27: done | K27: SAL-1765059347975-219 | M27: زبون
A28: مزرعة | B28: =IF(A28="","",IFERROR(VLOOKUP(A28, Stock_New!A:M, 2, FALSE),"")) -> بوكيه | C28: 2 | D28: =IF(A28="","",IFERROR(VLOOKUP(A28, Stock_New!A:M, 3, FALSE),"")) -> ذكريا | E28: =IF($A28="", "", IFERROR(VLOOKUP($A28, Stock_New!$A:$M, 6, FALSE), "")) -> 44.4 | F28: 50 | G28: 0.1 | H28: 99.9 | I28: done | J28: done | K28: SAL-1765059348003-390 | M28: زبون
A29: كتاب ديكور | B29: =IF(A29="","",IFERROR(VLOOKUP(A29, Stock_New!A:M, 2, FALSE),"")) -> كتب | C29: 10 | D29: =IF(A29="","",IFERROR(VLOOKUP(A29, Stock_New!A:M, 3, FALSE),"")) -> ذكريا | E29: =IF($A29="", "", IFERROR(VLOOKUP($A29, Stock_New!$A:$M, 6, FALSE), "")) -> 20.4 | F29: 25 | G29: 0.1 | H29: 249.8 | I29: done | J29: done | K29: SAL-1765059348029-887 | M29: زبونة
A30: طقم كاندي غزالة | B30: =IF(A30="","",IFERROR(VLOOKUP(A30, Stock_New!A:M, 2, FALSE),"")) -> مطبخ | C30: 1 | D30: =IF(A30="","",IFERROR(VLOOKUP(A30, Stock_New!A:M, 3, FALSE),"")) -> ذكريا | E30: =IF($A30="", "", IFERROR(VLOOKUP($A30, Stock_New!$A:$M, 6, FALSE), "")) -> 360 | F30: 400 | G30: 0.1 | H30: 399.6 | I30: done | J30: done | K30: SAL-1765059348052-580 | M30: عروسة
A31: مج بشاليموه | B31: =IF(A31="","",IFERROR(VLOOKUP(A31, Stock_New!A:M, 2, FALSE),"")) -> مطبخ | C31: 1 | D31: =IF(A31="","",IFERROR(VLOOKUP(A31, Stock_New!A:M, 3, FALSE),"")) -> ذكريا | E31: =IF($A31="", "", IFERROR(VLOOKUP($A31, Stock_New!$A:$M, 6, FALSE), "")) -> 90 | F31: 100 | G31: 0.1 | H31: 99.9 | I31: done | J31: done | K31: SAL-1765059348075-275 | M31: عروسة
... A55: بوكيه ريش وورد صغير | B55: =IF(A55="","",IFERROR(VLOOKUP(A55, Stock_New!A:M, 2, FALSE),"")) -> بوكيه | C55: 1 | D55: =IF(A55="","",IFERROR(VLOOKUP(A55, Stock_New!A:M, 3, FALSE),"")) -> ذكريا | E55: =IF($A55="", "", IFERROR(VLOOKUP($A55, Stock_New!$A:$M, 6, FALSE), "")) -> 132 | F55: 210 | G55: 0.1 | H55: 209.79 | I55: done | J55: done | K55: SAL-1765059349066-375 | M55: بونة
A56: اباجورة شكل 0 | B56: =IF(A56="","",IFERROR(VLOOKUP(A56, Stock_New!A:M, 2, FALSE),"")) -> كهربائيات | C56: 1 | D56: =IF(A56="","",IFERROR(VLOOKUP(A56, Stock_New!A:M, 3, FALSE),"")) -> شركة البطل | E56: =IF($A56="", "", IFERROR(VLOOKUP($A56, Stock_New!$A:$M, 6, FALSE), "")) -> 144 | F56: 220 | G56: 0.1 | H56: 219.78 | I56: done | J56: done | K56: SAL-1765059349111-105 | M56: حجز محمود محمد مصطفى | N56: =1750-500-300-300-400-250 -> 0
A57: بوت بشريطة دهبي | B57: =IF(A57="","",IFERROR(VLOOKUP(A57, Stock_New!A:M, 2, FALSE),"")) -> بوتات | C57: 2 | D57: =IF(A57="","",IFERROR(VLOOKUP(A57, Stock_New!A:M, 3, FALSE),"")) -> ذكريا | E57: =IF($A57="", "", IFERROR(VLOOKUP($A57, Stock_New!$A:$M, 6, FALSE), "")) -> 197 | F57: 220 | G57: 0.1 | H57: 439.56 | I57: done | J57: done | K57: SAL-1765059349159-109 | M57: حجز محمود محمد مصطفى | N57: =1750-500-300-300-400-250 -> 0
A58: شجرة مشمش خمس فروع | B58: =IF(A58="","",IFERROR(VLOOKUP(A58, Stock_New!A:M, 2, FALSE),"")) -> شجر | C58: 1 | D58: =IF(A58="","",IFERROR(VLOOKUP(A58, Stock_New!A:M, 3, FALSE),"")) -> ذكريا | E58: =IF($A58="", "", IFERROR(VLOOKUP($A58, Stock_New!$A:$M, 6, FALSE), "")) -> 390 | F58: 425 | G58: 0.1 | H58: 424.58 | I58: done | J58: done | K58: SAL-1765059349226-783 | M58: حجز محمود محمد مصطفى | N58: =1750-500-300-300-400-250 -> 0
A59: شجرة اريكا وسط | B59: =IF(A59="","",IFERROR(VLOOKUP(A59, Stock_New!A:M, 2, FALSE),"")) -> شجر | C59: 1 | D59: =IF(A59="","",IFERROR(VLOOKUP(A59, Stock_New!A:M, 3, FALSE),"")) -> ذكريا | E59: =IF($A59="", "", IFERROR(VLOOKUP($A59, Stock_New!$A:$M, 6, FALSE), "")) -> 675 | F59: 715 | G59: 0.1 | H59: 714.29 | I59: done | J59: done | K59: SAL-1765059349269-768 | M59: حجز محمود محمد مصطفى | N59: =1750-500-300-300-400-250 -> 0
A60: بوت صغير هااند ميد و 2 بوكيه | B60: =IF(A60="","",IFERROR(VLOOKUP(A60, Stock_New!A:M, 2, FALSE),"")) -> بوكيه | C60: 1 | D60: =IF(A60="","",IFERROR(VLOOKUP(A60, Stock_New!A:M, 3, FALSE),"")) -> ذكريا | E60: =IF($A60="", "", IFERROR(VLOOKUP($A60, Stock_New!$A:$M, 6, FALSE), "")) -> 282 | F60: 350 | G60: 0.1 | H60: 349.65 | I60: done | J60: done | K60: SAL-1765059349341-529 | M60: زبونة
A61: شجر ورق الوان | B61: =IF(A61="","",IFERROR(VLOOKUP(A61, Stock_New!A:M, 2, FALSE),"")) -> شجر | C61: 1 | D61: =IF(A61="","",IFERROR(VLOOKUP(A61, Stock_New!A:M, 3, FALSE),"")) -> ذكريا | E61: =IF($A61="", "", IFERROR(VLOOKUP($A61, Stock_New!$A:$M, 6, FALSE), "")) -> 192 | F61: 200 | G61: 0 | H61: 200 | I61: done | J61: done | K61: SAL-1765059349390-343 | M61: زبونة
A62: شجرة مكثفة | B62: =IF(A62="","",IFERROR(VLOOKUP(A62, Stock_New!A:M, 2, FALSE),"")) -> شجر | C62: 1 | D62: =IF(A62="","",IFERROR(VLOOKUP(A62, Stock_New!A:M, 3, FALSE),"")) -> ذكريا | E62: =IF($A62="", "", IFERROR(VLOOKUP($A62, Stock_New!$A:$M, 6, FALSE), "")) -> 372 | F62: 450 | G62: 0 | H62: 450 | I62: done | J62: done | K62: SAL-1765059349440-492 | M62: زبونة
A63: بوت بشريطة دهبي | B63: =IF(A63="","",IFERROR(VLOOKUP(A63, Stock_New!A:M, 2, FALSE),"")) -> بوتات | C63: 2 | D63: =IF(A63="","",IFERROR(VLOOKUP(A63, Stock_New!A:M, 3, FALSE),"")) -> ذكريا | E63: =IF($A63="", "", IFERROR(VLOOKUP($A63, Stock_New!$A:$M, 6, FALSE), "")) -> 197 | F63: 220 | G63: 0 | H63: 440 | I63: done | J63: done | K63: SAL-1765059349480-506 | M63: زبونة
...

Sheet Journal
A1: Date | B1: EntryID | C1: AccountDebit | D1: AccountCredit | E1: Amount | F1: Note
A2: 45998.011 | B2: SAL-1765059347259-242 | C2: COGS | D2: Inventory | E2: 210 | F2: COGS for بوت تركي
A3: 45998.011 | B3: SAL-1765059347259-242 | C3: Cash/AR | D3: Sales | E3: 240 | F3: Revenue for بوت تركي
A4: 45998.011 | B4: SAL-1765059347287-676 | C4: COGS | D4: Inventory | E4: 190 | F4: COGS for شجرة تركيب 12 ورقة
A5: 45998.011 | B5: SAL-1765059347287-676 | C5: Cash/AR | D5: Sales | E5: 150 | F5: Revenue for شجرة تركيب 12 ورقة
A6: 45998.011 | B6: SAL-1765059347322-954 | C6: COGS | D6: Inventory | E6: 140 | F6: COGS for بوكيه خزف
A7: 45998.011 | B7: SAL-1765059347322-954 | C7: Cash/AR | D7: Sales | E7: 150 | F7: Revenue for بوكيه خزف
A8: 45998.011 | B8: SAL-1765059347355-448 | C8: COGS | D8: Inventory | E8: 135 | F8: COGS for فازة خزف وورد احمر صغير
A9: 45998.011 | B9: SAL-1765059347355-448 | C9: Cash/AR | D9: Sales | E9: 195 | F9: Revenue for فازة خزف وورد احمر صغير
A10: 45998.011 | B10: SAL-1765059347379-326 | C10: COGS | D10: Inventory | E10: 185 | F10: COGS for فازة خزف وبوكيه ابيض كبير
A11: 45998.011 | B11: SAL-1765059347379-326 | C11: Cash/AR | D11: Sales | E11: 235 | F11: Revenue for فازة خزف وبوكيه ابيض كبير
A12: 45998.011 | B12: SAL-1765059347412-273 | C12: COGS | D12: Inventory | E12: 63 | F12: COGS for مزرعة
A13: 45998.011 | B13: SAL-1765059347412-273 | C13: Cash/AR | D13: Sales | E13: 100 | F13: Revenue for مزرعة
... A2551: 46172.911 | B2551: SAL-1780167096171-913 | C2551: Cash/AR | D2551: Sales | E2551: 200 | F2551: Revenue for علبة مناديل كريستال خلص

Sheet Logs_New
A1: TimeStamp | B1: العمود 2 | C1: ItemName | D1: Qty | E1: PurchasePrice | F1: ActualUnitPrice | G1: FinalUnitPrice | H1: TotalSale | I1: Profit | J1: Supplier | K1: RefRow | L1: Message | M1: User
A2: 46081.971 | B2: Manufacturing-Output | C2: بوت صغير | D2: 1 | E2: 22.75 | H2: 22.75 | J2: manufactured | K2: مقزم-شجر | L2: Product manufactured | M2: abdofwzy9@gmail.com
A3: 46081.971 | B3: Manufacturing-Output | C3: مقزم شجر | D3: 3 | E3: 14.083333 | H3: 42.25 | J3: manufactured | K3: مقزم-شجر | L3: Product manufactured | M3: abdofwzy9@gmail.com
A4: 46081.971 | B4: Manufacturing-Input | C4: شجرة صغيرة 3d | D4: 1 | E4: 65 | H4: 65 | J4: ذكريا | K4: مقزم-شجر | L4: Used in manufacturing | M4: abdofwzy9@gmail.com
A5: 46081.968 | B5: Manufacturing-Output | C5: بوت صغير | D5: 2 | E5: 22.75 | H5: 45.5 | J5: manufactured | K5: مقزم-شجر | L5: Product manufactured | M5: abdofwzy9@gmail.com
A6: 46081.968 | B6: Manufacturing-Output | C6: مقزم شجر | D6: 6 | E6: 14.083333 | H6: 84.5 | J6: manufactured | K6: مقزم-شجر | L6: Product manufactured | M6: abdofwzy9@gmail.com
A7: 46081.968 | B7: Manufacturing-Input | C7: شجرة صغيرة 3d | D7: 2 | E7: 65 | H7: 130 | J7: ذكريا | K7: مقزم-شجر | L7: Used in manufacturing | M7: abdofwzy9@gmail.com
A8: 46150.808 | B8: Mfg-In | C8: خضرة اللوان 18 | D8: 1 | E8: 110 | H8: 110 | J8: شركة الفرسان | K8: مقزم_خضرا _الوان | L8: Used | M8: abdofwzy9@gmail.com
A9: 46081.945 | B9: Manufacturing-Output | C9: بوكيه صغير | D9: 1 | E9: 28.5 | H9: 28.5 | J9: manufactured | K9: مقزم-شجر | L9: Product manufactured | M9: abdofwzy9@gmail.com
A10: 46081.945 | B10: Manufacturing-Output | C10: مقزم شجر | D10: 3 | E10: 22.166667 | H10: 66.5 | J10: manufactured | K10: مقزم-شجر | L10: Product manufactured | M10: abdofwzy9@gmail.com
A11: 46081.945 | B11: Manufacturing-Input | C11: بوت صغير مقزمات | D11: 3 | E11: 10 | H11: 30 | J11: شركة حسين علي | K11: مقزم-شجر | L11: Used in manufacturing | M11: abdofwzy9@gmail.com
A12: 46081.945 | B12: Manufacturing-Input | C12: شجرة صغيرة 3d | D12: 1 | E12: 65 | H12: 65 | J12: ذكريا | K12: مقزم-شجر | L12: Used in manufacturing | M12: abdofwzy9@gmail.com
A13: 46150.808 | B13: Mfg-In | C13: بروبلين 5سم عبدالله | D13: 18 | E13: 3.5 | H13: 63 | J13: شركة حسين علي | K13: مقزم_خضرا _الوان | L13: Used | M13: abdofwzy9@gmail.com
... A16: 46150.783 | B16: Mfg-In | C16: قصرية 20سم | D16: 1 | E16: 10 | H16: 10 | J16: عبدالفتاح | K16: شجرة_بنجامين_110سم | L16: Used | M16: abdofwzy9@gmail.com
A17: 46096.001 | B17: Purchase | C17: فازة بورسلين صغيرابيض مذهب | D17: 2 | E17: 250 | F17: 500 | G17: شركة حسين علي | H17: 500 | I17: ORD-1773525728614-154 | J17: Added 2 to stock (orderId:ORD-1773525728614-154) | K17: abdofwzy9@gmail.com
A18: 46096.001 | B18: Purchase | C18: فازة بورسلين وسط ابيض مذهب | D18: 2 | E18: 300 | F18: 600 | G18: شركة حسين علي | H18: 499 | I18: ORD-1773525728606-696 | J18: Added 2 to stock (orderId:ORD-1773525728606-696) | K18: abdofwzy9@gmail.com
A19: 46096.001 | B19: Purchase | C19: فازة بورسلين كبيرة ابيض مذهب | D19: 3 | E19: 400 | F19: 1200 | G19: شركة حسين علي | H19: 498 | J19: Added 3 to stock (orderId:) | K19: abdofwzy9@gmail.com
A20: 46150.729 | B20: Mfg-In | C20: بروبلين 5سم عبدالله | D20: 35 | E20: 3.5 | H20: 122.5 | J20: شركة حسين علي | K20: مقزم-قرنفل | L20: Used | M20: abdofwzy9@gmail.com
A21: 46066.906 | B21: Manufacturing-Output | C21: مقزم قرنفل | D21: 4 | E21: 10 | H21: 40 | J21: manufactured | K21: مقزم-قرنفل | L21: Product manufactured | M21: abdofwzy9@gmail.com
A22: 46066.906 | B22: Manufacturing-Input | C22: بوت صغير مقزمات | D22: 1 | E22: 10 | H22: 10 | J22: شركة حسين علي | K22: مقزم-قرنفل | L22: Used in manufacturing | M22: abdofwzy9@gmail.com
A23: 46066.906 | B23: Manufacturing-Input | C23: بوكية قرنفل | D23: 1 | E23: 30 | H23: 30 | J23: شركة حسين علي | K23: مقزم-قرنفل | L23: Used in manufacturing | M23: abdofwzy9@gmail.com
A24: 46150.729 | B24: Mfg-In | C24: قرنفل 2 | D24: 5 | E24: 30 | H24: 150 | J24: شركة حسين علي | K24: مقزم-قرنفل | L24: Used | M24: abdofwzy9@gmail.com
A25: 46172.911 | B25: Sale | C25: علبة مناديل كريستال خلص | D25: 1 | E25: 170 | F25: 200 | G25: 200 | H25: 200 | I25: 30 | J25: شركة الهضبة | K25: 1433 | L25: Sold (saleId:SAL-1780167096171-913) | M25: abdofwzy9@gmail.com
A26: 46083.001 | B26: Manufacturing-Output | C26: مقزم وردة حمرا قطيفة | D26: 7 | E26: 30 | H26: 210 | J26: manufactured | K26: مقزم-احمر-قطيفة | L26: Product manufactured | M26: abdofwzy9@gmail.com
A27: 46083.001 | B27: Manufacturing-Input | C27: بوت صغير مقزمات | D27: 7 | E27: 10 | H27: 70 | K27: مقزم-احمر-قطيفة | L27: Used in manufacturing | M27: abdofwzy9@gmail.com
A28: 46083.001 | B28: Manufacturing-Input | C28: بلدي قطيفة 7 فرع | D28: 1 | E28: 140 | H28: 140 | J28: شركة الفرسان | K28: مقزم-احمر-قطيفة | L28: Used in manufacturing | M28: abdofwzy9@gmail.com
A29: 46082.999 | B29: Manufacturing-Output | C29: مقزم وردة حمرا قطيفة | D29: 7 | E29: 20 | H29: 140 | J29: manufactured | K29: مقزم-احمر-قطيفة | L29: Product manufactured | M29: abdofwzy9@gmail.com
A30: 46082.999 | B30: Manufacturing-Input | C30: بلدي قطيفة 7 فرع | D30: 1 | E30: 140 | H30: 140 | J30: شركة الفرسان | K30: مقزم-احمر-قطيفة | L30: Used in manufacturing | M30: abdofwzy9@gmail.com
A31: 46082.997 | B31: Manufacturing-Output | C31: مقزم وردة حمرا قطيفة | D31: 7 | E31: 20 | H31: 140 | J31: manufactured | K31: مقزم-احمر-قطيفة | L31: Product manufactured | M31: abdofwzy9@gmail.com
A32: 46082.997 | B32: Manufacturing-Input | C32: بلدي قطيفة 7 فرع | D32: 1 | E32: 140 | H32: 140 | J32: شركة الفرسان | K32: مقزم-احمر-قطيفة | L32: Used in manufacturing | M32: abdofwzy9@gmail.com
A33: 46172.911 | B33: Sale | C33: بوكيه اربع وردات قطيفة | D33: 1 | E33: 56.666667 | F33: 70 | G33: 70 | H33: 70 | I33: 13.33 | J33: manufactured | K33: 1387 | L33: Sold (saleId:SAL-1780167096148-284) | M33: abdofwzy9@gmail.com
A34: 46075.022 | B34: Manufacturing-Output | C34: شجرة ياسمين 80سم | D34: 1 | E34: 315 | H34: 315 | J34: manufactured | K34: شجرة-ياسمين | L34: Product manufactured | M34: abdofwzy9@gmail.com
A35: 46075.022 | B35: Manufacturing-Input | C35: بوت وسط فاضي | D35: 1 | E35: 35 | H35: 35 | J35: عبدالفتاح | K35: شجرة-ياسمين | L35: Used in manufacturing | M35: abdofwzy9@gmail.com
A36: 46075.022 | B36: Manufacturing-Input | C36: قصرية 16سم | D36: 1 | E36: 5 | H36: 5 | J36: عبدالفتاح | K36: شجرة-ياسمين | L36: Used in manufacturing | M36: abdofwzy9@gmail.com
A37: 46075.022 | B37: Manufacturing-Input | C37: جزع 80 سم | D37: 1 | E37: 20 | H37: 20 | J37: عبدالفتاح | K37: شجرة-ياسمين | L37: Used in manufacturing | M37: abdofwzy9@gmail.com
A38: 46075.022 | B38: Manufacturing-Input | C38: ياسمين جيرمينجامبو | D38: 3 | E38: 85 | H38: 255 | J38: شركة الفرسان | K38: شجرة-ياسمين | L38: Used in manufacturing | M38: abdofwzy9@gmail.com
A39: 46172.911 | B39: Sale | C39: ورد ديكور محمد رشدي | D39: 2 | E39: 103 | F39: 150 | G39: 150 | H39: 300 | I39: 94 | J39: سنتر محمد رشدي | K39: 1380 | L39: Sold (saleId:SAL-1780167096123-816) | M39: abdofwzy9@gmail.com
A40: 46172.911 | B40: Sale | C40: طقم دوناتس | D40: 1 | E40: 110 | F40: 160 | G40: 160 | H40: 160 | I40: 50 | J40: شركة حسين علي | K40: 1373 | L40: Sold (saleId:SAL-1780167096100-996) | M40: abdofwzy9@gmail.com
A41: 46074.018 | B41: Purchase | C41: دابل فيس 18م | D41: 12 | E41: 28 | F41: 336 | H41: 447 | I41: ORD-1771626318054-237 | J41: Added 12 to stock (orderId:ORD-1771626318054-237) | K41: abdofwzy9@gmail.com
A42: 46074.018 | B42: Purchase | C42: دابل فيس 14م | D42: 12 | E42: 20 | F42: 240 | H42: 446 | I42: ORD-1771626318049-306 | J42: Added 12 to stock (orderId:ORD-1771626318049-306) | K42: abdofwzy9@gmail.com
...

Sheet SystemStatus
A1: Date | B1: Process | C1: Message | D1: Count
A2: 45997.557 | B2: Orders | C2: Processed orders into stock | D2: 243
A3: 45997.577 | B3: Sales | C3: Processed sales | D3: 157
A4: 45997.577 | B4: Sales | C4: Warnings: Not enough stock for بوكيه بلاستيك ورد مقفول وورد صغير. Required: 1, Available: 0 (sale row: 18) | Not enough stock for فازة خزف وورد احمر صغير. Required: 2, Available: 0 (sale row: 19) | Not enough stock for بوكيه خزف مقسوم ورد شبه التاج. Required: 1, Available: 0 (sale row: 79) | Not enough stock for بوكيه ورد احمر صغير واخضر. Required: 1, Available: 0 (sale row: 108) | Not enough stock for بوكيه بلاستيك و ريش واخضر عرايس:). Required: 1, Available: 0 (sale row: 109) | D4: 12
A5: 45997.58 | B5: Sales | C5: Processed sales | D5: 0
A6: 45997.58 | B6: Sales | C6: Warnings: Not enough stock for بوكيه بلاستيك ورد مقفول وورد صغير. Required: 1, Available: 0 (sale row: 18) | Not enough stock for فازة خزف وورد احمر صغير. Required: 2, Available: 0 (sale row: 19) | Not enough stock for بوكيه خزف مقسوم ورد شبه التاج. Required: 1, Available: 0 (sale row: 79) | Not enough stock for بوكيه ورد احمر صغير واخضر. Required: 1, Available: 0 (sale row: 108) | Not enough stock for بوكيه بلاستيك و ريش واخضر عرايس:). Required: 1, Available: 0 (sale row: 109) | D6: 12
A7: 45997.583 | B7: Sales | C7: Processed sales | D7: 5
